<?xml version="1.0" ?>
<robot xmlns:xacro="http://ros.org/wiki/xacro">
	<xacro:macro name="ca20n" params="prefix">
		<!-- link list -->
		<link name="${prefix}base_link">
			<visual>
			        <origin rpy="0 0 0"/>
				<geometry>
					<mesh filename="package://ca20n_description/meshes/visual/ca20n_base_link.stl" />
				</geometry>
				<material name="blue">
					<color rgba="0 0 1 1"/>
				</material>
			</visual>
<!--
			<collision>
			        <origin rpy="0 0 0"/>
				<geometry>
					<mesh filename="package://ca20n_description/meshes/collision/ca20n_base_link.stl" />
				</geometry>
				<material name="yellow">
					<color rgba="0 1 1 1"/>
				</material>
			</collision>
-->
		</link>
		<link name="${prefix}link_1">
			<visual>
				<geometry>
					<mesh filename="package://ca20n_description/meshes/visual/ca20n_link_1.stl"/>
				</geometry>
				<material name="silver">
					<color rgba="0.8 0.8 0.8 1"/>
				</material>
			</visual>
<!--
			<collision>
				<geometry>
					<mesh filename="package://ca20n_description/meshes/collision/ca20n_link_1.stl" />
				</geometry>
				<material name="yellow"/>
			</collision>
-->
		</link>
		<link name="${prefix}link_2">
			<visual>
				<geometry>
					<mesh filename="package://ca20n_description/meshes/visual/ca20n_link_2.stl"/>
				</geometry>
				<material name="blue"/>
			</visual>
<!--
			<collision>
				<geometry>
					<mesh filename="package://ca20n_description/meshes/collision/ca20n_link_2.stl" />
				</geometry>
				<material name="yellow"/>
			</collision>
-->
		</link>
		<link name="${prefix}link_3">
			<visual>
				<geometry>
					<mesh filename="package://ca20n_description/meshes/visual/ca20n_link_3.stl"/>
				</geometry>
				<material name="blue"/>
			</visual>
<!--
			<collision>
				<geometry>
					<mesh filename="package://ca20n_description/meshes/collision/ca20n_link_3.stl" />
				</geometry>
				<material name="yellow"/>
			</collision>
-->
		</link>
		<link name="${prefix}link_4">
			<visual>
				<!-- <origin rpy="0 0 3.1416" xyz="0 0 0"/> -->
				<geometry>
					<mesh filename="package://ca20n_description/meshes/visual/ca20n_link_4.stl"/>
				</geometry>
				<material name="silver"/>
			</visual>
<!--
			<collision>
				<geometry>
					<mesh filename="package://ca20n_description/meshes/collision/ca20n_link_4.stl" />
				</geometry>
				<material name="yellow"/>
			</collision>
-->
		</link>
		<link name="${prefix}link_5">
			<visual>
				<geometry>
					<mesh filename="package://ca20n_description/meshes/visual/ca20n_link_5.stl"/>
				</geometry>
				<material name="blue"/>
			</visual>
<!--
			<collision>
				<geometry>
					<mesh filename="package://ca20n_description/meshes/collision/ca20n_link_5.stl" />
				</geometry>
				<material name="yellow"/>
			</collision>
-->
		</link>
		<link name="${prefix}link_6">
			<visual>
				<geometry>
					<mesh filename="package://ca20n_description/meshes/visual/ca20n_link_6.stl" />
				</geometry>
				<material name="silver"/>
			</visual>
<!--
			<collision>
				<geometry>
					<mesh filename="package://motoman_mh5_support/meshes/collision/ca20n_link_6.stl" />
				</geometry>
				<material name="yellow"/>
			</collision>
-->
		<!-- </link>
		<link name="${prefix}spray_gun">
			<visual>
				<geometry>
					<cylinder radius="0.03" length="0.2"/>
				</geometry>
				<material name="blue"/>
			</visual> -->
		</link><link name="${prefix}EndFlange"/>
		<!-- end of link list -->
		<!-- joint list -->
		<joint name="${prefix}joint_1" type="revolute">
			<parent link="${prefix}base_link"/>
			<child link="${prefix}link_1"/>
			<origin xyz="0 0 0.465" rpy="0 0 0"/>
			<axis xyz="0 0 1" />
			<limit lower="${-pi}" upper="${pi}" effort="100" velocity="${150*pi/180}" />
		</joint>
		<joint name="${prefix}joint_2" type="revolute">
			<parent link="${prefix}link_1"/>
			<child link="${prefix}link_2"/>
			<origin xyz="0.15 0 0" rpy="0 0 0"/>
			<axis xyz="0 1 0" />
			<limit lower="${-105*pi/180}" upper="${155*pi/180}" effort="100" velocity="${165*pi/180}" />
		</joint>
		<joint name="${prefix}joint_3" type="revolute">
			<parent link="${prefix}link_2"/>
			<child link="${prefix}link_3"/>
			<origin xyz="0 0 0.77" rpy="0 0 0"/>
			<axis xyz="0 -1 0" />
			<limit lower="${-163*pi/180}" upper="${150*pi/180}" effort="100" velocity="${140*pi/180}" />
		</joint>
		<joint name="${prefix}joint_4" type="revolute">
			<parent link="${prefix}link_3"/>
			<child link="${prefix}link_4"/>
			<origin xyz="0.0 0 0.805" rpy="0 0 0"/>
			<axis xyz="0 0 1" />
			<limit lower="${-3*pi/2}" upper="${3*pi/2}" effort="100" velocity="${395*pi/180}" />
		</joint>
		<joint name="${prefix}joint_5" type="revolute">
			<parent link="${prefix}link_4"/>
			<child link="${prefix}link_5"/>
			<origin xyz="0 0 0" rpy="0 0 0"/>
			<axis xyz="0 1 0" />
			<limit lower="${-135*pi/180}" upper="${135*pi/180}" effort="100" velocity="${2*pi}" />
		</joint>
		<joint name="${prefix}joint_6" type="revolute">
			<parent link="${prefix}link_5"/>
			<child link="${prefix}link_6"/>
			<origin xyz="0.0 0 0.095" rpy="0 0 0"/>
			<axis xyz="0 0 1" />
			<limit lower="${-2*pi}" upper="${2*pi}" effort="100" velocity="${605*pi/180}" />
		</joint>
		<joint name="${prefix}EndFlange" type="fixed">
			<parent link="${prefix}link_6"/>
			<child link="${prefix}EndFlange"/>
			<origin xyz="0 0 0" rpy="0 0 0"/>
		</joint>
		<!-- end of joint list -->
	</xacro:macro>
</robot>
